<?xml version='1.0'?>
<sdf version='1.5'> <!--- latest version is 1.9? -->
  <model name="bigfootbot">
    <!-- While we are creating the robot, we want Gazebo’s physics engine to ignore the robot
    so we set static to true -->
    <static>false</static>

    <!-- ****************** ROBOT BASE FOOTPRINT ***************************  -->
    <link name="base_footprint">
      <pose>0.0 0.0 0.0 0.0 0.0 0.0</pose>
    </link>

    <!-- ********************** ROBOT BASE *********************************  -->
    <link name="base_link">
      <!--pose>0 0 0 0 0 0</pose-->
      <collision name="base_collision">
        <pose>0 0 0 0 0 0</pose>
        <geometry>
          <box>
            <size>0.75 0.45 0.20</size>
          </box>
        </geometry>
      </collision>

      <visual name="base_visual">
        <pose>0.375 -0.225 -0.1 0 0 1.5708</pose>
        <geometry>
          <mesh>
            <uri>model://bigfootbot/meshes/frame_with_covers_2_m.stl</uri>
            <scale>1.0 1.0 1.0</scale>
          </mesh>
        </geometry>
        <material>
          <ambient>1.0 0.0 0.0 1.0</ambient> <!-- RGB [0..1] + alpha [0..1]-->
          <diffuse>1.0 0.0 0.0 1.0</diffuse>
          <specular>0.0 0.0 0.0 1.0</specular>
          <emissive>0.0 0.0 0.0 1.0</emissive>
        </material>
      </visual>

    </link>
    <!-- END OF ROBOT BASE -->

    <!-- *********************** DRIVE WHEELS ******************************  -->
    <!-- front left wheel-->
    <link name="drivewhl_fl_link">
      <pose>0.275 0.295 -0.1 0 0 0</pose>
      
      <collision name="drivewhl_fl_collision">
        <pose>0 0 0 1.5708 0 0</pose>
        <geometry>
          <cylinder>
            <radius>0.165</radius>
            <length>0.1</length>
          </cylinder>
        </geometry>
      </collision>

      <visual name="drivewhl_fl_visual">
        <pose>0 0 0 0 0 3.1416</pose>
        <geometry>
          <mesh>
            <uri>model://bigfootbot/meshes/wheel_m.stl</uri>
            <scale>1.0 1.0 1.0</scale>
          </mesh>
        </geometry>
        <material>
          <ambient>0.5 0.5 0.5 1.0</ambient> <!-- RGB [0..1] + alpha [0..1]-->
          <diffuse>0.5 0.5 0.5 1.0</diffuse>
          <specular>0.0 0.0 0.0 1.0</specular>
          <emissive>0.0 0.0 0.0 1.0</emissive>
        </material>
      </visual>

    </link>

    <!-- front right wheel-->
    <link name="drivewhl_fr_link">
      <pose>0.275 -0.295 -0.1 0 0 0</pose>
      
      <collision name="drivewhl_fr_collision">
        <pose>0 0 0 1.5708 0 0</pose>
        <geometry>
          <cylinder>
            <radius>0.165</radius>
            <length>0.1</length>
          </cylinder>
        </geometry>
      </collision>

      <visual name="drivewhl_fr_visual">
        <geometry>
          <mesh>
            <uri>model://bigfootbot/meshes/wheel_m.stl</uri>
            <scale>1.0 1.0 1.0</scale>
          </mesh>
        </geometry>
        <material>
          <ambient>0.5 0.5 0.5 1.0</ambient> <!-- RGB [0..1] + alpha [0..1]-->
          <diffuse>0.5 0.5 0.5 1.0</diffuse>
          <specular>0.0 0.0 0.0 1.0</specular>
          <emissive>0.0 0.0 0.0 1.0</emissive>
        </material>
      </visual>

    </link>

    <!-- back left wheel-->
    <link name="drivewhl_bl_link">
      <pose>-0.275 0.295 -0.1 0 0 0</pose>
      
      <collision name="drivewhl_bl_collision">
        <pose>0 0 0 1.5708 0 0</pose>
        <geometry>
          <cylinder>
            <radius>0.165</radius>
            <length>0.1</length>
          </cylinder>
        </geometry>
      </collision>

      <visual name="drivewhl_bl_visual">
        <pose>0 0 0 0 0 3.1416</pose>
        <geometry>
          <mesh>
            <uri>model://bigfootbot/meshes/wheel_m.stl</uri>
            <scale>1.0 1.0 1.0</scale>
          </mesh>
        </geometry>
        <material>
          <ambient>0.5 0.5 0.5 1.0</ambient> <!-- RGB [0..1] + alpha [0..1]-->
          <diffuse>0.5 0.5 0.5 1.0</diffuse>
          <specular>0.0 0.0 0.0 1.0</specular>
          <emissive>0.0 0.0 0.0 1.0</emissive>
        </material>
      </visual>

    </link>

    <!-- back right wheel-->
    <link name="drivewhl_br_link">
      <pose>-0.275 -0.295 -0.1 0 0 0</pose>
      
      <collision name="drivewhl_br_collision">
        <pose>0 0 0 1.5708 0 0</pose>
        <geometry>
          <cylinder>
            <radius>0.165</radius>
            <length>0.1</length>
          </cylinder>
        </geometry>
      </collision>

      <visual name="drivewhl_br_visual">
        <geometry>
          <mesh>
            <uri>model://bigfootbot/meshes/wheel_m.stl</uri>
            <scale>1.0 1.0 1.0</scale>
          </mesh>
        </geometry>
        <material>
          <ambient>0.5 0.5 0.5 1.0</ambient> <!-- RGB [0..1] + alpha [0..1]-->
          <diffuse>0.5 0.5 0.5 1.0</diffuse>
          <specular>0.0 0.0 0.0 1.0</specular>
          <emissive>0.0 0.0 0.0 1.0</emissive>
        </material>
      </visual>

    </link>>
    <!-- END OF DRIVE WHEELS -->

    <!-- ************************ JOINTS ***********************************  -->
    <!-- Pose of the joint is the same as the child link frame -->
    <!-- Axis is the axis of rotation relative to the child link frame -->
    
    <joint name="base_joint" type="fixed">
      <parent>base_footprint</parent>
      <child>base_link</child>
      <pose>0 0 0 0 0 0</pose>
    </joint>

    <joint name="drivewhl_fl_joint" type="revolute">
      <parent>base_link</parent>
      <child>drivewhl_fl_link</child>
      <pose>0 0 0 0 0 0</pose>
      <axis>
        <xyz>0 1 0</xyz>
      </axis>
    </joint>

    <joint name="drivewhl_fr_joint" type="revolute">
      <parent>base_link</parent>
      <child>drivewhl_fr_link</child>
      <pose>0 0 0 0 0 0</pose>
      <axis>
        <xyz>0 1 0</xyz>
      </axis>
    </joint>

    <joint name="drivewhl_bl_joint" type="revolute">
      <parent>base_link</parent>
      <child>drivewhl_bl_link</child>
      <pose>0 0 0 0 0 0</pose>
      <axis>
        <xyz>0 1 0</xyz>
      </axis>
    </joint>

    <joint name="drivewhl_br_joint" type="revolute">
      <parent>base_link</parent>
      <child>drivewhl_br_link</child>
      <pose>0 0 0 0 0 0</pose>
      <axis>
        <xyz>0 1 0</xyz>
      </axis>
    </joint>

    <!--joint name="imu_joint" type="fixed">
      <parent>base_link</parent>
      <child>imu_link</child>
      <pose>0 0 0 0 0 0</pose>
    </joint>  

    <joint name="gps_joint" type="fixed">
      <parent>base_link</parent>
      <child>gps_link</child>
      <pose>0 0 0 0 0 0</pose>
    </joint-->  
  </model>
</sdf>