<?xml version='1.0'?>

<robot name="barrelbot" xmlns:xacro="http://www.ros.org/wiki/xacro">
  
  <!--xacro:include filename="$(find littlebot)/urdf/_d435i.urdf.xacro"/--> 

  <xacro:include filename="barrelbot_inertial_macros.xacro" />
  
  <xacro:include filename="./controllers/brlb_gazebo_control.xacro" />
  
  <!-- MATERIALS -->

  <material name="green">
    <color rgba="0 1 0 1"/>
  </material>

  <material name="black">
    <color rgba="0 0 0 1"/>
  </material>

  <material name="red">
    <color rgba="1 0 0 1"/>
  </material>

  <material name="gray">
    <color rgba="0.5 0.5 0.5 1"/>
  </material>

  <!-- base_footprint is a fictitious link(frame) that is on the ground right below base_link origin -->
  <!--link name="base_footprint" /-->

  <!-- BASE (CHASSIS) LINK -->

  <link name="base_link">
    <visual>
      <origin xyz="0 0 0.14" rpy="0 0 0"/> <!-- origin is located at the bottom in the center of the cylinder -->
      <geometry>
        <cylinder length="0.28" radius="0.215"/>
      </geometry>
      <material name="green"/>
    </visual>
    <collision>
      <origin xyz="0 0 0.14" rpy="0 0 0"/> <!-- origin is located at the bottom in the center of the cylinder -->
      <geometry>
        <cylinder length="0.28" radius="0.215"/>
      </geometry>      
    </collision>
    <xacro:inertial_cylinder mass="3.0" length="0.28" radius="0.215">
      <origin xyz="0 0 0.14" rpy="0 0 0"/> <!-- origin is the same as for visual and collision -->
    </xacro:inertial_cylinder>
  </link>

  <!--joint name="base_joint" type="fixed">
    <origin xyz="0 0 0.16" rpy="0 0 0" />
    <parent link="base_footprint"/>
    <child link="base_link"/>
  </joint-->

  <!-- LIDAR LINK -->

  <joint name="lidar_joint" type="fixed">
    <parent link="base_link"/>
    <child link="lidar_link"/>
    <origin xyz="0 0 0.31" rpy="0 0 0"/> <!-- z=0.31 = 0.14(vertical middle of robot body cylinder) +0.17-->
  </joint>
  
  <link name="lidar_link">
    <visual>
      <geometry>
        <cylinder length="0.06" radius="0.05"/>
      </geometry>
      <material name="black"/>
    </visual>
  </link>

  <!--joint name="base_to_camera" type="fixed">
    <parent link="base_link"/>
    <child link="camera_bottom_screw_frame"/>
    <origin xyz="0.17 0 0.17" rpy="0 0 0"/>
  </joint-->

  <!--link name="camera_link">
    <visual>
      <origin xyz="0 0 0" rpy="0 0 0" />
      <geometry>
        <box size="0.025 0.09 0.025"/>
      </geometry>
      <material name="gray"/>
    </visual>
  </link-->
  
  <!-- camera D435i model (<joint> block URDF is generated inside _d435i.urdf.xacro->_d435.urdf.xacro) -->
  <!--xacro:sensor_d435i parent="base_link" use_nominal_extrinsics="false">
    <origin xyz="0.17 0 0.31" rpy="0 0 0"/> (z=0.31 = 0.14(vertical middle of robot body cylinder +0.17)
  </xacro:sensor_d435i-->


  <!-- LEFT WHEEL LINK -->

  <joint name="left_wheel_joint" type="continuous">
    <parent link="base_link"/>
    <child link="left_wheel"/>
    <origin xyz="0 0.15 0" rpy="0 0 0"/> <!-- left wheel is located 15cm to the left of the center of the robot -->
    <axis xyz="0 1 0"/> <!-- axis of rotation is the y-axis -->
  </joint>

  <link name="left_wheel">
    <visual>
      <origin xyz="0 0 0" rpy="${pi/2} 0 0"/> <!-- pi/2 = 90 degrees or 1.57 radians (1 radian = 57.2958 degrees) -->
      <geometry>
        <cylinder length="0.02" radius="0.065"/> <!-- Diamater of the wheel is 130mm, width is 20mm -->
      </geometry>
      <material name="red"/>
    </visual>
    
    <collision>
      <origin xyz="0 0 0" rpy="${pi/2} 0 0"/> <!-- pi/2 = 90 degrees or 1.57 radians (1 radian = 57.2958 degrees) -->
      <geometry>
        <cylinder length="0.02" radius="0.065"/> <!-- Diamater of the wheel is 130mm, width is 20mm -->
      </geometry>
    </collision>
    
    <xacro:inertial_cylinder mass="0.1" length="0.02" radius="0.065">
      <origin xyz="0 0 0" rpy="${pi/2} 0 0"/> <!-- origin is the same as for visual and collision -->
    </xacro:inertial_cylinder>
  </link>
  
  <!-- RIGHT WHEEL LINK -->

  <joint name="right_wheel_joint" type="continuous">
    <parent link="base_link"/>
    <child link="right_wheel"/>
    <origin xyz="0 -0.15 0" rpy="0 0 0"/> <!-- right wheel is located 15cm to the right of the center of the robot -->
    <axis xyz="0 1 0"/> <!-- axis of rotation is the y-axis -->
  </joint>

  <link name="right_wheel">    
    <visual>
      <origin xyz="0 0 0" rpy="${pi/2} 0 0"/> <!-- pi/2 = 90 degrees or 1.57 radians (1 radian = 57.2958 degrees) -->
      <geometry>
        <cylinder length="0.02" radius="0.065"/> <!-- Diamater of the wheel is 130mm, width is 20mm -->
      </geometry>
      <material name="red"/>
    </visual>
    
    <collision>
      <origin xyz="0 0 0" rpy="${pi/2} 0 0"/> <!-- pi/2 = 90 degrees or 1.57 radians (1 radian = 57.2958 degrees) -->
      <geometry>
        <cylinder length="0.02" radius="0.065"/> <!-- Diamater of the wheel is 130mm, width is 20mm -->
      </geometry>
    </collision>
    
    <xacro:inertial_cylinder mass="0.1" length="0.02" radius="0.065">
      <origin xyz="0 0 0" rpy="${pi/2} 0 0"/> <!-- origin is the same as for visual and collision -->
    </xacro:inertial_cylinder>
  </link>


  <!-- FRONT CASTER WHEEL LINK-->

  <joint name="caster_front_wheel_joint" type="fixed">
    <parent link="base_link"/>
    <child link="caster_front_wheel"/>
    <origin xyz="0.15 0 0" rpy="0 0 0"/> <!-- caster wheel is located 15cm to the front of the center of the robot -->
  </joint>

  <link name="caster_front_wheel">
    <visual>
      <origin xyz="0 0 0" rpy= "0 0 0"/>
      <geometry>
        <sphere radius="0.06" />
      </geometry>
      <material name="gray"/>
    </visual>
    
    <collision>
      <origin xyz="0 0 0" rpy= "0 0 0"/>
      <geometry>
        <sphere radius="0.06" />
      </geometry>      
    </collision>
    
    <xacro:inertial_sphere mass="0.1" radius="0.06">
      <origin xyz="0 0 0" rpy="0 0 0"/> <!-- origin is the same as for visual and collision -->
    </xacro:inertial_sphere>
  </link>

  <!-- BACK CASTER WHEEL LINK-->

  <joint name="caster_back_wheel_joint" type="fixed">
    <parent link="base_link"/>
    <child link="caster_back_wheel"/>
    <origin xyz="-0.15 0 0" rpy="0 0 0"/> <!-- caster wheel is located 15cm to the back of the center of the robot -->
  </joint>

  <link name="caster_back_wheel">
    <visual>
      <origin xyz="0 0 0" rpy= "0 0 0"/>
      <geometry>
        <sphere radius="0.06" />
      </geometry>
      <material name="gray"/>
    </visual>
    
    <collision>
      <origin xyz="0 0 0" rpy= "0 0 0"/>
      <geometry>
        <sphere radius="0.06" />
      </geometry>
    </collision>
    
    <xacro:inertial_sphere mass="0.1" radius="0.06">
      <origin xyz="0 0 0" rpy="0 0 0"/> <!-- origin is the same as for visual and collision -->
    </xacro:inertial_sphere>
  </link>

</robot>
   